Workbook

Sheet enrollments (5)
A1: account_key | B1: status | C1: join_date | D1: cancel_date | E1: days_to_cancel | F1: is_udacity | G1: is_canceled
A2: 448 | B2: canceled | C2: 41953 | D2: 42018 | E2: 65 | F2: TRUE | G2: TRUE
A3: 448 | B3: canceled | C3: 41948 | D3: 41953 | E3: 5 | F3: TRUE | G3: TRUE
A4: 448 | B4: canceled | C4: 42031 | D4: 42031 | E4: 0 | F4: TRUE | G4: TRUE
A5: 448 | B5: canceled | C5: 41953 | D5: 41953 | E5: 0 | F5: TRUE | G5: TRUE
A6: 448 | B6: current | C6: 42073 | F6: TRUE | G6: FALSE
A7: 448 | B7: canceled | C7: 42018 | D7: 42031 | E7: 13 | F7: TRUE | G7: TRUE
A8: 448 | B8: canceled | C8: 42031 | D8: 42073 | E8: 42 | F8: TRUE | G8: TRUE
A9: 448 | B9: canceled | C9: 42031 | D9: 42031 | E9: 0 | F9: TRUE | G9: TRUE
A10: 448 | B10: canceled | C10: 42031 | D10: 42031 | E10: 0 | F10: TRUE | G10: TRUE
A11: 700 | B11: canceled | C11: 41953 | D11: 41959 | E11: 6 | F11: FALSE | G11: TRUE
A12: 429 | B12: canceled | C12: 41953 | D12: 42073 | E12: 120 | F12: FALSE | G12: TRUE
A13: 429 | B13: canceled | C13: 42073 | D13: 42172 | E13: 99 | F13: FALSE | G13: TRUE
A14: 60 | B14: canceled | C14: 41953 | D14: 42018 | E14: 65 | F14: FALSE | G14: TRUE
A15: 60 | B15: canceled | C15: 42018 | D15: 42095 | E15: 77 | F15: FALSE | G15: TRUE
A16: 60 | B16: current | C16: 42095 | F16: FALSE | G16: FALSE
A17: 1300 | B17: canceled | C17: 41953 | D17: 41959 | E17: 6 | F17: FALSE | G17: TRUE
A18: 369 | B18: current | C18: 41953 | F18: FALSE | G18: FALSE
A19: 322 | B19: canceled | C19: 41953 | D19: 42037 | E19: 84 | F19: FALSE | G19: TRUE
A20: 322 | B20: canceled | C20: 42047 | D20: 42047 | E20: 0 | F20: FALSE | G20: TRUE
A21: 322 | B21: canceled | C21: 42047 | D21: 42073 | E21: 26 | F21: FALSE | G21: TRUE
A22: 322 | B22: current | C22: 42073 | F22: FALSE | G22: FALSE
A23: 336 | B23: current | C23: 41953 | F23: FALSE | G23: FALSE
A24: 553 | B24: current | C24: 41953 | F24: FALSE | G24: FALSE
A25: 584 | B25: canceled | C25: 41953 | D25: 42018 | E25: 65 | F25: FALSE | G25: TRUE
A26: 584 | B26: canceled | C26: 42018 | D26: 42073 | E26: 55 | F26: FALSE | G26: TRUE
A27: 584 | B27: current | C27: 42073 | F27: FALSE | G27: FALSE
A28: 1006 | B28: canceled | C28: 41953 | D28: 41960 | E28: 7 | F28: FALSE | G28: TRUE
A29: 458 | B29: canceled | C29: 41953 | D29: 42095 | E29: 142 | F29: FALSE | G29: TRUE
A30: 458 | B30: canceled | C30: 42098 | D30: 42100 | E30: 2 | F30: FALSE | G30: TRUE
A31: 458 | B31: current | C31: 42100 | F31: FALSE | G31: FALSE
A32: 1058 | B32: canceled | C32: 41953 | D32: 42018 | E32: 65 | F32: FALSE | G32: TRUE
A33: 1058 | B33: canceled | C33: 42018 | D33: 42073 | E33: 55 | F33: FALSE | G33: TRUE
A34: 1058 | B34: current | C34: 42073 | F34: FALSE | G34: FALSE
A35: 206 | B35: current | C35: 41953 | F35: FALSE | G35: FALSE
A36: 45 | B36: canceled | C36: 41953 | D36: 42073 | E36: 120 | F36: FALSE | G36: TRUE
A37: 45 | B37: current | C37: 42073 | F37: FALSE | G37: FALSE
A38: 315 | B38: canceled | C38: 41953 | D38: 42141 | E38: 188 | F38: FALSE | G38: TRUE
A39: 604 | B39: current | C39: 41953 | F39: FALSE | G39: FALSE
A40: 204 | B40: current | C40: 41953 | F40: FALSE | G40: FALSE
...

Sheet CLEAN DATA
A1: =PROPER(TRIM('enrollments (5)'!A1)) -> Account_Key | B1: =PROPER(TRIM('enrollments (5)'!B1)) -> Status | C1: =PROPER(TRIM('enrollments (5)'!C1)) -> Join_Date | D1: =PROPER(TRIM('enrollments (5)'!D1)) -> Cancel_Date | E1: =PROPER(TRIM('enrollments (5)'!E1)) -> Days_To_Cancel | F1: =PROPER(TRIM('enrollments (5)'!F1)) -> Is_Udacity | G1: =PROPER(TRIM('enrollments (5)'!G1)) -> Is_Canceled
A2: =TRIM('enrollments (5)'!A2) -> 448 | B2: =PROPER(TRIM('enrollments (5)'!B2)) -> Canceled | C2: 41953 | D2: 42018 | E2: =IF(D2="","",D2-C2) -> 65 | F2: TRUE | G2: =B2="canceled" -> TRUE
A3: =TRIM('enrollments (5)'!A3) -> 448 | B3: =PROPER(TRIM('enrollments (5)'!B3)) -> Canceled | C3: 41948 | D3: 41953 | E3: =IF(D3="","",D3-C3) -> 5 | F3: TRUE | G3: =B3="canceled" -> TRUE
A4: =TRIM('enrollments (5)'!A4) -> 448 | B4: =PROPER(TRIM('enrollments (5)'!B4)) -> Canceled | C4: 42031 | D4: 42031 | E4: =IF(D4="","",D4-C4) -> 0 | F4: TRUE | G4: =B4="canceled" -> TRUE
A5: =TRIM('enrollments (5)'!A5) -> 448 | B5: =PROPER(TRIM('enrollments (5)'!B5)) -> Canceled | C5: 41953 | D5: 41953 | E5: =IF(D5="","",D5-C5) -> 0 | F5: TRUE | G5: =B5="canceled" -> TRUE
A6: =TRIM('enrollments (5)'!A6) -> 448 | B6: =PROPER(TRIM('enrollments (5)'!B6)) -> Current | C6: 42073 | E6: =IF(D6="","",D6-C6) | F6: TRUE | G6: =B6="canceled" -> FALSE
A7: =TRIM('enrollments (5)'!A7) -> 448 | B7: =PROPER(TRIM('enrollments (5)'!B7)) -> Canceled | C7: 42018 | D7: 42031 | E7: =IF(D7="","",D7-C7) -> 13 | F7: TRUE | G7: =B7="canceled" -> TRUE
A8: =TRIM('enrollments (5)'!A8) -> 448 | B8: =PROPER(TRIM('enrollments (5)'!B8)) -> Canceled | C8: 42031 | D8: 42073 | E8: =IF(D8="","",D8-C8) -> 42 | F8: TRUE | G8: =B8="canceled" -> TRUE
A9: =TRIM('enrollments (5)'!A11) -> 700 | B9: =PROPER(TRIM('enrollments (5)'!B11)) -> Canceled | C9: 41953 | D9: 41959 | E9: =IF(D9="","",D9-C9) -> 6 | F9: FALSE | G9: =B9="canceled" -> TRUE
A10: =TRIM('enrollments (5)'!A12) -> 429 | B10: =PROPER(TRIM('enrollments (5)'!B12)) -> Canceled | C10: 41953 | D10: 42073 | E10: =IF(D10="","",D10-C10) -> 120 | F10: FALSE | G10: =B10="canceled" -> TRUE
A11: =TRIM('enrollments (5)'!A13) -> 429 | B11: =PROPER(TRIM('enrollments (5)'!B13)) -> Canceled | C11: 42073 | D11: 42172 | E11: =IF(D11="","",D11-C11) -> 99 | F11: FALSE | G11: =B11="canceled" -> TRUE
A12: =TRIM('enrollments (5)'!A14) -> 60 | B12: =PROPER(TRIM('enrollments (5)'!B14)) -> Canceled | C12: 41953 | D12: 42018 | E12: =IF(D12="","",D12-C12) -> 65 | F12: FALSE | G12: =B12="canceled" -> TRUE
A13: =TRIM('enrollments (5)'!A15) -> 60 | B13: =PROPER(TRIM('enrollments (5)'!B15)) -> Canceled | C13: 42018 | D13: 42095 | E13: =IF(D13="","",D13-C13) -> 77 | F13: FALSE | G13: =B13="canceled" -> TRUE
A14: =TRIM('enrollments (5)'!A16) -> 60 | B14: =PROPER(TRIM('enrollments (5)'!B16)) -> Current | C14: 42095 | E14: =IF(D14="","",D14-C14) | F14: FALSE | G14: =B14="canceled" -> FALSE
A15: =TRIM('enrollments (5)'!A17) -> 1300 | B15: =PROPER(TRIM('enrollments (5)'!B17)) -> Canceled | C15: 41953 | D15: 41959 | E15: =IF(D15="","",D15-C15) -> 6 | F15: FALSE | G15: =B15="canceled" -> TRUE
A16: =TRIM('enrollments (5)'!A18) -> 369 | B16: =PROPER(TRIM('enrollments (5)'!B18)) -> Current | C16: 41953 | E16: =IF(D16="","",D16-C16) | F16: FALSE | G16: =B16="canceled" -> FALSE
A17: =TRIM('enrollments (5)'!A19) -> 322 | B17: =PROPER(TRIM('enrollments (5)'!B19)) -> Canceled | C17: 41953 | D17: 42037 | E17: =IF(D17="","",D17-C17) -> 84 | F17: FALSE | G17: =B17="canceled" -> TRUE
A18: =TRIM('enrollments (5)'!A20) -> 322 | B18: =PROPER(TRIM('enrollments (5)'!B20)) -> Canceled | C18: 42047 | D18: 42047 | E18: =IF(D18="","",D18-C18) -> 0 | F18: FALSE | G18: =B18="canceled" -> TRUE
A19: =TRIM('enrollments (5)'!A21) -> 322 | B19: =PROPER(TRIM('enrollments (5)'!B21)) -> Canceled | C19: 42047 | D19: 42073 | E19: =IF(D19="","",D19-C19) -> 26 | F19: FALSE | G19: =B19="canceled" -> TRUE
A20: =TRIM('enrollments (5)'!A22) -> 322 | B20: =PROPER(TRIM('enrollments (5)'!B22)) -> Current | C20: 42073 | E20: =IF(D20="","",D20-C20) | F20: FALSE | G20: =B20="canceled" -> FALSE
A21: =TRIM('enrollments (5)'!A23) -> 336 | B21: =PROPER(TRIM('enrollments (5)'!B23)) -> Current | C21: 41953 | E21: =IF(D21="","",D21-C21) | F21: FALSE | G21: =B21="canceled" -> FALSE
A22: =TRIM('enrollments (5)'!A24) -> 553 | B22: =PROPER(TRIM('enrollments (5)'!B24)) -> Current | C22: 41953 | E22: =IF(D22="","",D22-C22) | F22: FALSE | G22: =B22="canceled" -> FALSE
A23: =TRIM('enrollments (5)'!A25) -> 584 | B23: =PROPER(TRIM('enrollments (5)'!B25)) -> Canceled | C23: 41953 | D23: 42018 | E23: =IF(D23="","",D23-C23) -> 65 | F23: FALSE | G23: =B23="canceled" -> TRUE
A24: =TRIM('enrollments (5)'!A26) -> 584 | B24: =PROPER(TRIM('enrollments (5)'!B26)) -> Canceled | C24: 42018 | D24: 42073 | E24: =IF(D24="","",D24-C24) -> 55 | F24: FALSE | G24: =B24="canceled" -> TRUE
A25: =TRIM('enrollments (5)'!A27) -> 584 | B25: =PROPER(TRIM('enrollments (5)'!B27)) -> Current | C25: 42073 | E25: =IF(D25="","",D25-C25) | F25: FALSE | G25: =B25="canceled" -> FALSE
A26: =TRIM('enrollments (5)'!A28) -> 1006 | B26: =PROPER(TRIM('enrollments (5)'!B28)) -> Canceled | C26: 41953 | D26: 41960 | E26: =IF(D26="","",D26-C26) -> 7 | F26: FALSE | G26: =B26="canceled" -> TRUE
A27: =TRIM('enrollments (5)'!A29) -> 458 | B27: =PROPER(TRIM('enrollments (5)'!B29)) -> Canceled | C27: 41953 | D27: 42095 | E27: =IF(D27="","",D27-C27) -> 142 | F27: FALSE | G27: =B27="canceled" -> TRUE
A28: =TRIM('enrollments (5)'!A30) -> 458 | B28: =PROPER(TRIM('enrollments (5)'!B30)) -> Canceled | C28: 42098 | D28: 42100 | E28: =IF(D28="","",D28-C28) -> 2 | F28: FALSE | G28: =B28="canceled" -> TRUE
A29: =TRIM('enrollments (5)'!A31) -> 458 | B29: =PROPER(TRIM('enrollments (5)'!B31)) -> Current | C29: 42100 | E29: =IF(D29="","",D29-C29) | F29: FALSE | G29: =B29="canceled" -> FALSE
A30: =TRIM('enrollments (5)'!A32) -> 1058 | B30: =PROPER(TRIM('enrollments (5)'!B32)) -> Canceled | C30: 41953 | D30: 42018 | E30: =IF(D30="","",D30-C30) -> 65 | F30: FALSE | G30: =B30="canceled" -> TRUE
A31: =TRIM('enrollments (5)'!A33) -> 1058 | B31: =PROPER(TRIM('enrollments (5)'!B33)) -> Canceled | C31: 42018 | D31: 42073 | E31: =IF(D31="","",D31-C31) -> 55 | F31: FALSE | G31: =B31="canceled" -> TRUE
A32: =TRIM('enrollments (5)'!A34) -> 1058 | B32: =PROPER(TRIM('enrollments (5)'!B34)) -> Current | C32: 42073 | E32: =IF(D32="","",D32-C32) | F32: FALSE | G32: =B32="canceled" -> FALSE
A33: =TRIM('enrollments (5)'!A35) -> 206 | B33: =PROPER(TRIM('enrollments (5)'!B35)) -> Current | C33: 41953 | E33: =IF(D33="","",D33-C33) | F33: FALSE | G33: =B33="canceled" -> FALSE
A34: =TRIM('enrollments (5)'!A36) -> 45 | B34: =PROPER(TRIM('enrollments (5)'!B36)) -> Canceled | C34: 41953 | D34: 42073 | E34: =IF(D34="","",D34-C34) -> 120 | F34: FALSE | G34: =B34="canceled" -> TRUE
A35: =TRIM('enrollments (5)'!A37) -> 45 | B35: =PROPER(TRIM('enrollments (5)'!B37)) -> Current | C35: 42073 | E35: =IF(D35="","",D35-C35) | F35: FALSE | G35: =B35="canceled" -> FALSE
A36: =TRIM('enrollments (5)'!A38) -> 315 | B36: =PROPER(TRIM('enrollments (5)'!B38)) -> Canceled | C36: 41953 | D36: 42141 | E36: =IF(D36="","",D36-C36) -> 188 | F36: FALSE | G36: =B36="canceled" -> TRUE
A37: =TRIM('enrollments (5)'!A39) -> 604 | B37: =PROPER(TRIM('enrollments (5)'!B39)) -> Current | C37: 41953 | E37: =IF(D37="","",D37-C37) | F37: FALSE | G37: =B37="canceled" -> FALSE
A38: =TRIM('enrollments (5)'!A40) -> 204 | B38: =PROPER(TRIM('enrollments (5)'!B40)) -> Current | C38: 41953 | E38: =IF(D38="","",D38-C38) | F38: FALSE | G38: =B38="canceled" -> FALSE
A39: =TRIM('enrollments (5)'!A41) -> 408 | B39: =PROPER(TRIM('enrollments (5)'!B41)) -> Canceled | C39: 41953 | D39: 42073 | E39: =IF(D39="","",D39-C39) -> 120 | F39: FALSE | G39: =B39="canceled" -> TRUE
A40: =TRIM('enrollments (5)'!A42) -> 408 | B40: =PROPER(TRIM('enrollments (5)'!B42)) -> Canceled | C40: 42073 | D40: 42095 | E40: =IF(D40="","",D40-C40) -> 22 | F40: FALSE | G40: =B40="canceled" -> TRUE
...

Sheet Sheet2
A3: Count of Account_Key | B3: Column Labels
A4: Row Labels | B4: FALSE | C4: TRUE | D4: Grand Total
A5: Canceled | B5: 971 | C5: 13 | D5: 984
A6: Current | B6: 649 | C6: 3 | D6: 652
A7: Grand Total | B7: 1620 | C7: 16 | D7: 1636

Sheet Sheet1
